const num1 = 10

try {
    num1 = 2
} catch(err) {
    console.log(`Erro: ${err}`)
}